<?xml version="1.0" ?>
<robot name="elevator">
    <material name="white">
        <color rgba="1.0 1.0 1.0 1.0"/>
    </material>
        <material name="red">
        <color rgba="1 0.4 0.4 1"/>
    </material>
    <link name="base_link">
        <visual>
            <geometry>
                <box size="0.1 0.1 0.1"/>
            </geometry>
            <material name="white"/>
        </visual>
        <collision>
            <geometry>
                <box size="0.1 0.1 0.1"/>
            </geometry>
        </collision>
        <inertial>
            <mass value="0.0"/>
            <inertia ixx="0.0" ixy="0.0" ixz="0.0" iyy="0.0" iyz="0.0" izz="0.0"/>
        </inertial>
    </link>
    <link name="elevator">
        <inertial>
            <origin rpy="0 0 0" xyz="0.0 0.0 0.0"/>
            <mass value="0.1"/>
            <inertia ixx="0" ixy="0.1" ixz="0.1" iyy="0" iyz="0.1" izz="0"/>
        </inertial>
        <visual>
            <origin rpy="1.57 0 0" xyz="0.0 -0.01 0"/>
            <geometry>
                <mesh filename="cylinder.obj" scale="0.1 0.1 0.1"/>
            </geometry>
            <material name="red"/>
        </visual>
        <collision>
            <origin rpy="1.57 0 0" xyz="0.0 -0.01 0"/>
            <geometry>
	 	        <mesh filename="cylinder.obj" scale="0.1 0.1 0.1"/>
            </geometry>
        </collision>
    </link>
    <joint name="basetoelevator" type="continuous">
        <parent link="base_link"/>
        <child link="elevator"/>
        <origin xyz="0.0 -0.05 0.0"/>
        <axis xyz="0.0 1.0 0.0"/>
        <!-- <limit lower="-0.3" upper=".3"/> -->
    </joint>
    <link name="prism_rod">
        <visual>
            <geometry>
                <cylinder radius="0.01" length="0.1"/>
            </geometry>
            <material name="white"/>
            <origin xyz="0.0 0.0 0.05"/>
        </visual>
        <collision>
            <geometry>
                <cylinder radius="0.01" length="0.1"/>
            </geometry>
            <origin xyz="0.0 0.0 0.05"/>
        </collision>
        <inertial>
            <mass value="0.01"/>
            <inertia ixx="0.01" ixy="0.01" ixz="0.01" iyy="0.01" iyz="0.01" izz="0.01"/>
        </inertial>
    </link>
    <joint name="elevatortorod" type="prismatic">
        <parent link="elevator"/>
        <child link="prism_rod"/>
        <origin xyz="0.0 -0.01 0.05"/>
        <axis xyz="0.0 0.0 1.0"/>
        <limit lower="0.0" upper=".01"/>
    </joint>
    <link name="frame_hor">
        <visual>
            <geometry>
                <cylinder radius="0.01" length="0.5"/>
            </geometry>
            <material name="white"/>
            <origin rpy="0.0 -1.57 0.0" xyz="0.25 0.0 0.0"/>
        </visual>
        <collision>
            <geometry>
                <cylinder radius="0.01" length="0.5"/>
            </geometry>
            <origin rpy="0.0 -1.57 0.0" xyz="0.25 0.0 0.0"/>
        </collision>
        <inertial>
            <mass value="0.1"/>
            <inertia ixx="0.1" ixy="0.1" ixz="0.1" iyy="0.1" iyz="0.1" izz="0.1"/>
        </inertial>
    </link>
    <joint name="rodtoframe" type="continuous">
        <parent link="prism_rod"/>
        <child link="frame_hor"/>
        <origin xyz="0.0 0.0 0.1"/>
        <axis xyz="0.0 1.0 0.0"/>
        <!-- <limit lower="-0.175" upper=".175"/> -->
    </joint>
    <link name="frame_ver">
        <visual>
            <geometry>
                <cylinder radius="0.01" length="0.5"/>
            </geometry>
            <material name="white"/>
            <origin rpy="0.0 0 0.0" xyz="0.0 0.0 -0.25"/>
        </visual>
        <collision>
            <geometry>
                <cylinder radius="0.01" length="0.5"/>
            </geometry>
            <origin rpy="0.0 0 0.0" xyz="0.0 0.0 -0.25"/>
        </collision>
        <inertial>
            <mass value="0.1"/>
            <inertia ixx="0.1" ixy="0.1" ixz="0.1" iyy="0.1" iyz="0.1" izz="0.1"/>
        </inertial>
    </link>
    <joint name="frame" type="fixed">
        <parent link="frame_hor"/>
        <child link="frame_ver"/>
        <origin xyz="0.5 0.0 0.0"/>
    </joint>
    <link name="frame_end">
        <collision>
            <geometry>
                <sphere radius="0.001"/>
            </geometry>
            <origin xyz="0.0 0.0 -0.001"/>
        </collision>
    </link>
    <joint name="frame_connector" type="fixed">
        <parent link="frame_ver"/>
        <child link="frame_end"/>
        <origin xyz="0.0 0.0 -0.5"/>
    </joint>
</robot>